<?xml version="1.0" encoding="utf-8"?>
<!-- =================================================================================== -->
<!-- |    This document was autogenerated by xacro from /home/sunwenbin/catkin_ws/src/nanocar_description-master/urdf/nanocar_description.urdf.xacro | -->
<!-- |    EDITING THIS FILE BY HAND IS NOT RECOMMENDED                                 | -->
<!-- =================================================================================== -->
<robot name="NanoCar">
  &gt;
  
  <gazebo reference="/base_link">
    <material>Gazebo/DarkGrey</material>
  </gazebo>
  <gazebo reference="/front_left_wheel_link">
    <mu1>0.5</mu1>
    <mu2>0.5</mu2>
    <kp>500000.0</kp>
    <kd>10.0</kd>
    <minDepth>0.001</minDepth>
    <maxVel>1.0</maxVel>
    <fdir1>1 0 0</fdir1>
    <material>Gazebo/FlatBlack</material>
  </gazebo>
  <gazebo reference="/front_right_wheel_link">
    <mu1>0.5</mu1>
    <mu2>0.5</mu2>
    <kp>500000.0</kp>
    <kd>10.0</kd>
    <minDepth>0.001</minDepth>
    <maxVel>1.0</maxVel>
    <fdir1>1 0 0</fdir1>
    <material>Gazebo/FlatBlack</material>
  </gazebo>
  <gazebo reference="/back_left_wheel_link">
    <mu1>0.5</mu1>
    <mu2>0.5</mu2>
    <kp>500000.0</kp>
    <kd>10.0</kd>
    <minDepth>0.001</minDepth>
    <maxVel>1.0</maxVel>
    <fdir1>1 0 0</fdir1>
    <material>Gazebo/FlatBlack</material>
  </gazebo>
  <gazebo reference="/back_right_wheel_link">
    <mu1>0.5</mu1>
    <mu2>0.5</mu2>
    <kp>500000.0</kp>
    <kd>10.0</kd>
    <minDepth>0.001</minDepth>
    <maxVel>1.0</maxVel>
    <fdir1>1 0 0</fdir1>
    <material>Gazebo/FlatBlack</material>
  </gazebo>
  <gazebo>
    <plugin filename="libgazebo_ros_skid_steer_drive.so" name="skid_steer_drive_controller">
      <updateRate>100.0</updateRate>
      <robotNamespace>/</robotNamespace>
      <leftFrontJoint>front_left_wheel_joint</leftFrontJoint>
      <rightFrontJoint>front_right_wheel_joint</rightFrontJoint>
      <leftRearJoint>back_left_wheel_joint</leftRearJoint>
      <rightRearJoint>back_right_wheel_joint</rightRearJoint>
      <wheelSeparation>0.144</wheelSeparation>
      <wheelDiameter>0.065</wheelDiameter>
      <robotBaseFrame>base_footprint</robotBaseFrame>
      <torque>20</torque>
      <commandTopic>cmd_vel</commandTopic>
      <odometryTopic>odom</odometryTopic>
      <odometryFrame>odom</odometryFrame>
      <covariance_x>0.0001</covariance_x>
      <covariance_y>0.0001</covariance_y>
      <covariance_yaw>0.0001</covariance_yaw>
      <broadcastTF>true</broadcastTF>
    </plugin>
  </gazebo>
  <gazebo reference="/imu">
    <sensor name="imu" type="imu">
      <always_on>true</always_on>
      <visualize>false</visualize>
    </sensor>
    <material>Gazebo/FlatBlack</material>
  </gazebo>
  <gazebo>
    <plugin filename="libgazebo_ros_imu.so" name="imu_plugin">
      <alwaysOn>true</alwaysOn>
      <bodyName>/imu</bodyName>
      <frameName>imu</frameName>
      <topicName>imu</topicName>
      <serviceName>imu_service</serviceName>
      <gaussianNoise>0.0</gaussianNoise>
      <updateRate>0</updateRate>
      <imu>
        <noise>
          <type>gaussian</type>
          <rate>
            <mean>0.0</mean>
            <stddev>2e-4</stddev>
            <bias_mean>0.0000075</bias_mean>
            <bias_stddev>0.0000008</bias_stddev>
          </rate>
          <accel>
            <mean>0.0</mean>
            <stddev>1.7e-2</stddev>
            <bias_mean>0.1</bias_mean>
            <bias_stddev>0.001</bias_stddev>
          </accel>
        </noise>
      </imu>
    </plugin>
  </gazebo>
  <gazebo reference="/base_laser_link">
    <material>Gazebo/FlatBlack</material>
    <sensor name="rplidar_sensor" type="ray">
      <pose>0 0 0 0 0 0</pose>
      <visualize>false</visualize>
      <update_rate>7</update_rate>
      <ray>
        <scan>
          <horizontal>
            <samples>720</samples>
            <resolution>0.5</resolution>
            <min_angle>0.0</min_angle>
            <max_angle>6.28319</max_angle>
          </horizontal>
        </scan>
        <range>
          <min>0.120</min>
          <max>12.0</max>
          <resolution>0.015</resolution>
        </range>
        <noise>
          <type>gaussian</type>
          <mean>0.0</mean>
          <stddev>0.01</stddev>
        </noise>
      </ray>
      <plugin filename="libgazebo_ros_laser.so" name="gazebo_ros_rplidar_controller">
        <topicName>scan</topicName>
        <frameName>base_laser_link</frameName>
      </plugin>
    </sensor>
  </gazebo>
  <gazebo reference="/base_camera_link">
    <sensor name="csi Camera" type="camera">
      <always_on>true</always_on>
      <visualize>false</visualize>
      <camera>
        <horizontal_fov>1.085595</horizontal_fov>
        <image>
          <width>640</width>
          <height>480</height>
          <format>R8G8B8</format>
        </image>
        <clip>
          <near>0.03</near>
          <far>100</far>
        </clip>
      </camera>
      <plugin filename="libgazebo_ros_camera.so" name="camera_controller">
        <alwaysOn>true</alwaysOn>
        <updateRate>30.0</updateRate>
        <cameraName>/</cameraName>
        <frameName>base_camera_link</frameName>
        <imageTopicName>image_raw</imageTopicName>
        <cameraInfoTopicName>camera_info</cameraInfoTopicName>
        <hackBaseline>0.07</hackBaseline>
        <distortionK1>0.0</distortionK1>
        <distortionK2>0.0</distortionK2>
        <distortionK3>0.0</distortionK3>
        <distortionT1>0.0</distortionT1>
        <distortionT2>0.0</distortionT2>
      </plugin>
    </sensor>
  </gazebo>
  <link name="/base_footprint"/>
  <joint name="base_joint" type="fixed">
    <parent link="/base_footprint"/>
    <child link="/base_link"/>
    <origin rpy="0 0 0" xyz="0.0 0.0 0.012"/>
  </joint>
  <link name="/base_link">
    <inertial>
      <origin rpy="0 0 0" xyz="0.0555446452540713 0.000671669256433499 0.0266509782546839"/>
      <mass value="0.360847988626614"/>
      <inertia ixx="0.000516397641128697" ixy="1.1957324992993E-05" ixz="0.000120152725218978" iyy="0.00154603495385803" iyz="-8.72108816656556E-06" izz="0.00169469610791314"/>
    </inertial>
    <visual>
      <origin rpy="0 0 0" xyz="0 0 0"/>
      <geometry>
        <mesh filename="package://nanocar_description/meshes/base_link.STL"/>
      </geometry>
      <material name="">
        <color rgba="1 1 1 1"/>
      </material>
    </visual>
    <collision>
      <origin rpy="0 0 0" xyz="0 0 0"/>
      <geometry>
        <mesh filename="package://nanocar_description/meshes/base_link.STL"/>
      </geometry>
    </collision>
  </link>
  <link name="/front_left_wheel_link">
    <inertial>
      <origin rpy="0 0 0" xyz="-0.00010538637242985 -0.00550462033646019 2.15695517002956E-14"/>
      <mass value="0.0561341413767672"/>
      <inertia ixx="2.45349618443393E-05" ixy="3.40792909820246E-07" ixz="2.2300311878363E-18" iyy="4.23289891465669E-05" iyz="-2.1064917599381E-17" izz="2.45284373383242E-05"/>
    </inertial>
    <visual>
      <origin rpy="0 0 0" xyz="0 0 0"/>
      <geometry>
        <mesh filename="package://nanocar_description/meshes/front_left_wheel_link.STL"/>
      </geometry>
      <material name="">
        <color rgba="0.109803921568627 0.109803921568627 0.109803921568627 1"/>
      </material>
    </visual>
    <collision>
      <origin rpy="0 0 0" xyz="0 0 0"/>
      <geometry>
        <mesh filename="package://nanocar_description/meshes/front_left_wheel_link.STL"/>
      </geometry>
    </collision>
  </link>
  <joint name="front_left_wheel_joint" type="continuous">
    <origin rpy="0 0 0" xyz="0.14398 0.087243 0.0179"/>
    <parent link="/base_link"/>
    <child link="/front_left_wheel_link"/>
    <axis xyz="0 1 0"/>
  </joint>
  <link name="/front_right_wheel_link">
    <inertial>
      <origin rpy="0 0 0" xyz="6.76035723146257E-05 0.00550521399163428 2.15868989350554E-14"/>
      <mass value="0.0561341413761839"/>
      <inertia ixx="2.45311221758638E-05" ixy="2.18636454271762E-07" ixz="-2.52922597607164E-19" iyy="4.23328288149757E-05" iyz="4.02318858428609E-18" izz="2.45284373382953E-05"/>
    </inertial>
    <visual>
      <origin rpy="0 0 0" xyz="0 0 0"/>
      <geometry>
        <mesh filename="package://nanocar_description/meshes/front_right_wheel_link.STL"/>
      </geometry>
      <material name="">
        <color rgba="0.109803921568627 0.109803921568627 0.109803921568627 1"/>
      </material>
    </visual>
    <collision>
      <origin rpy="0 0 0" xyz="0 0 0"/>
      <geometry>
        <mesh filename="package://nanocar_description/meshes/front_right_wheel_link.STL"/>
      </geometry>
    </collision>
  </link>
  <joint name="front_right_wheel_joint" type="continuous">
    <origin rpy="0 0 0" xyz="0.14278 -0.087247 0.0179"/>
    <parent link="/base_link"/>
    <child link="/front_right_wheel_link"/>
    <axis xyz="0 1 0"/>
  </joint>
  <link name="/back_left_wheel_link">
    <inertial>
      <origin rpy="0 0 0" xyz="-1.11022302462516E-16 -0.00550562905918096 0"/>
      <mass value="0.0561341413751443"/>
      <inertia ixx="2.45284373382495E-05" ixy="7.62335823185991E-18" ixz="-6.93955014485814E-22" iyy="4.23355136524843E-05" iyz="-1.73414696438044E-17" izz="2.45284373382495E-05"/>
    </inertial>
    <visual>
      <origin rpy="0 0 0" xyz="0 0 0"/>
      <geometry>
        <mesh filename="package://nanocar_description/meshes/back_left_wheel_link.STL"/>
      </geometry>
      <material name="">
        <color rgba="0.109803921568627 0.109803921568627 0.109803921568627 1"/>
      </material>
    </visual>
    <collision>
      <origin rpy="0 0 0" xyz="0 0 0"/>
      <geometry>
        <mesh filename="package://nanocar_description/meshes/back_left_wheel_link.STL"/>
      </geometry>
    </collision>
  </link>
  <joint name="back_left_wheel_joint" type="continuous">
    <origin rpy="0 0 5.2577E-15" xyz="-0.00015 0.08725 0.0179"/>
    <parent link="/base_link"/>
    <child link="/back_left_wheel_link"/>
    <axis xyz="0 1 0"/>
  </joint>
  <link name="/back_right_wheel_link">
    <inertial>
      <origin rpy="0 0 0" xyz="5.55111512312578E-17 0.00550562905918101 6.93889390390723E-18"/>
      <mass value="0.0561341413751443"/>
      <inertia ixx="2.45284373382496E-05" ixy="7.52903077889808E-18" ixz="7.29027186707092E-22" iyy="4.23355136524844E-05" iyz="1.73420673069565E-17" izz="2.45284373382496E-05"/>
    </inertial>
    <visual>
      <origin rpy="0 0 0" xyz="0 0 0"/>
      <geometry>
        <mesh filename="package://nanocar_description/meshes/back_right_wheel_link.STL"/>
      </geometry>
      <material name="">
        <color rgba="0.109803921568627 0.109803921568627 0.109803921568627 1"/>
      </material>
    </visual>
    <collision>
      <origin rpy="0 0 0" xyz="0 0 0"/>
      <geometry>
        <mesh filename="package://nanocar_description/meshes/back_right_wheel_link.STL"/>
      </geometry>
    </collision>
  </link>
  <joint name="back_right_wheel_joint" type="continuous">
    <origin rpy="0 0 0" xyz="0.00015 -0.08725 0.0179"/>
    <parent link="/base_link"/>
    <child link="/back_right_wheel_link"/>
    <axis xyz="0 1 0"/>
  </joint>
  <link name="/base_laser_link">
    <inertial>
      <origin rpy="0 0 0" xyz="0.0523572786618226 -0.000415129505920292 -0.0724378427604165"/>
      <mass value="0.587950004839672"/>
      <inertia ixx="0.0021356987454402" ixy="1.06647658432416E-05" ixz="-0.000134594037561808" iyy="0.00294196763294724" iyz="9.42320675642704E-06" izz="0.00449915941190477"/>
    </inertial>
    <visual>
      <origin rpy="0 0 0" xyz="0 0 0"/>
      <geometry>
        <mesh filename="package://nanocar_description/meshes/base_laser_link.STL"/>
      </geometry>
      <material name="">
        <color rgba="1 1 1 1"/>
      </material>
    </visual>
    <collision>
      <origin rpy="0 0 0" xyz="0 0 0"/>
      <geometry>
        <mesh filename="package://nanocar_description/meshes/base_laser_link.STL"/>
      </geometry>
    </collision>
  </link>
  <joint name="laser_joint" type="fixed">
    <origin rpy="0 0 3.1416" xyz="0.11423 0 0.096"/>
    <parent link="/base_link"/>
    <child link="/base_laser_link"/>
    <axis xyz="0 0 1"/>
  </joint>
  <link name="/base_camera_link">
    <inertial>
      <origin rpy="0 0 0" xyz="-0.00453469422999369 2.77555756156289E-17 0.00179125965737485"/>
      <mass value="0.00100487943921971"/>
      <inertia ixx="7.5567739127561E-08" ixy="-4.52878601912423E-25" ixz="1.37755038601046E-09" iyy="3.9493893215179E-08" iyz="3.67972463900956E-24" izz="4.01523294449251E-08"/>
    </inertial>
    <visual>
      <origin rpy="0 0 0" xyz="0 0 0"/>
      <geometry>
        <mesh filename="package://nanocar_description/meshes/base_camera_link.STL"/>
      </geometry>
      <material name="">
        <color rgba="1 1 1 1"/>
      </material>
    </visual>
    <collision>
      <origin rpy="0 0 0" xyz="0 0 0"/>
      <geometry>
        <mesh filename="package://nanocar_description/meshes/base_camera_link.STL"/>
      </geometry>
    </collision>
  </link>
  <joint name="camera_joint" type="fixed">
    <origin rpy="0 0 0" xyz="0.167 0 0.0723"/>
    <parent link="/base_link"/>
    <child link="/base_camera_link"/>
    <axis xyz="1 0 0"/>
  </joint>
  <link name="/imu">
    <inertial>
      <origin rpy="0 0 0" xyz="2.77555756156289E-17 0 -0.00346762589928058"/>
      <mass value="0.000834"/>
      <inertia ixx="1.72751258992805E-08" ixy="-1.34149734347123E-23" ixz="8.58268730243352E-26" iyy="1.01251258992806E-08" iyz="1.22503149789368E-25" izz="2.3801E-08"/>
    </inertial>
    <visual>
      <origin rpy="0 0 0" xyz="0 0 0"/>
      <geometry>
        <mesh filename="package://nanocar_description/meshes/imu.STL"/>
      </geometry>
      <material name="">
        <color rgba="1 1 1 1"/>
      </material>
    </visual>
    <collision>
      <origin rpy="0 0 0" xyz="0 0 0"/>
      <geometry>
        <mesh filename="package://nanocar_description/meshes/imu.STL"/>
      </geometry>
    </collision>
  </link>
  <joint name="imu_joint" type="fixed">
    <origin rpy="7.5597E-18 -1.1042E-17 -5.8164E-14" xyz="-0.006172 -0.0010254 0.08269"/>
    <parent link="/base_link"/>
    <child link="/imu"/>
    <axis xyz="0 0 0"/>
  </joint>
</robot>

